<robot
  name="igvc">
  <link
    name="base_link">
    <inertial>
      <origin
        xyz="-0.32774 0.34915 0.10574"
        rpy="0 0 0" />
      <mass
        value="4.1331" />
      <inertia
        ixx="0.18727"
        ixy="-5.4284E-05"
        ixz="0.022471"
        iyy="0.28211"
        iyz="-4.1854E-05"
        izz="0.4159" />
    </inertial>
    <visual>
      <origin
        xyz="0 0 0"
        rpy="0 0 0" />
      <geometry>
        <mesh
          filename="package://robot_description/meshes/base_link.STL" />
      </geometry>
      <material
        name="">
        <color
          rgba="0.5 0.5 0.5 1" />
      </material>
    </visual>
    <collision>
      <origin
        xyz="0 0 0"
        rpy="0 0 0" />
      <geometry>
        <mesh
          filename="package://robot_description/meshes/base_link.STL" />
      </geometry>
    </collision>
  </link>
  <link
    name="left_wheel_link">
    <inertial>
      <origin
        xyz="3.359E-05 2.839E-05 0.038042"
        rpy="0 0 0" />
      <mass
        value="3.3664" />
      <inertia
        ixx="0.025859"
        ixy="1.737E-06"
        ixz="7.2454E-07"
        iyy="0.025868"
        iyz="6.1242E-07"
        izz="0.049429" />
    </inertial>
    <visual>
      <origin
        xyz="0 0 0"
        rpy="0 0 0" />
      <geometry>
        <mesh
          filename="package://robot_description/meshes/left_wheel_link.STL" />
      </geometry>
      <material
        name="">
        <color
          rgba="0.18 0.18 0.31 1" />
      </material>
    </visual>
    <collision>
      <origin
        xyz="0 0 0"
        rpy="0 0 0" />
      <geometry>
        <mesh
          filename="package://robot_description/meshes/left_wheel_link.STL" />
      </geometry>
    </collision>
  </link>
  <joint
    name="left_wheel_joint"
    type="continuous">
    <origin
      xyz="-0.19368 0.58103 -0.060325"
      rpy="1.5708 0.11459 -3.1416" />
    <parent
      link="base_link" />
    <child
      link="left_wheel_link" />
    <axis
      xyz="0 0 1" />
  </joint>
  <link
    name="right_wheel_link">
    <inertial>
      <origin
        xyz="3.359E-05 2.839E-05 -0.038158"
        rpy="0 0 0" />
      <mass
        value="3.3664" />
      <inertia
        ixx="0.025859"
        ixy="1.737E-06"
        ixz="7.2454E-07"
        iyy="0.025868"
        iyz="6.1242E-07"
        izz="0.049429" />
    </inertial>
    <visual>
      <origin
        xyz="0 0 0"
        rpy="0 0 0" />
      <geometry>
        <mesh
          filename="package://robot_description/meshes/right_wheel_link.STL" />
      </geometry>
      <material
        name="">
        <color
          rgba="0.18 0.18 0.31 1" />
      </material>
    </visual>
    <collision>
      <origin
        xyz="0 0 0"
        rpy="0 0 0" />
      <geometry>
        <mesh
          filename="package://robot_description/meshes/right_wheel_link.STL" />
      </geometry>
    </collision>
  </link>
  <joint
    name="right_wheel_joint"
    type="continuous">
    <origin
      xyz="-0.19368 0.041275 -0.060325"
      rpy="1.5708 0 0" />
    <parent
      link="base_link" />
    <child
      link="right_wheel_link" />
    <axis
      xyz="0 0 1" />
  </joint>
  <link
    name="back_wheel_link">
    <inertial>
      <origin
        xyz="2.2169E-05 1.8737E-05 0.025108"
        rpy="0 0 0" />
      <mass
        value="0.96781" />
      <inertia
        ixx="0.0032385"
        ixy="2.1753E-07"
        ixz="9.0737E-08"
        iyy="0.0032396"
        iyz="7.6695E-08"
        izz="0.0061901" />
    </inertial>
    <visual>
      <origin
        xyz="0 0 0"
        rpy="0 0 0" />
      <geometry>
        <mesh
          filename="package://robot_description/meshes/back_wheel_link.STL" />
      </geometry>
      <material
        name="">
        <color
          rgba="1 0.5 0 1" />
      </material>
    </visual>
    <collision>
      <origin
        xyz="0 0 0"
        rpy="0 0 0" />
      <geometry>
        <mesh
          filename="package://robot_description/meshes/back_wheel_link.STL" />
      </geometry>
    </collision>
  </link>
  <joint
    name="back_wheel_joint"
    type="continuous">
    <origin
      xyz="-0.76733 0.32525 -0.10058"
      rpy="1.5708 -0.057299 3.1416" />
    <parent
      link="base_link" />
    <child
      link="back_wheel_link" />
    <axis
      xyz="0 0 1" />
  </joint>
  <link
    name="laser_link">
    <inertial>
      <origin
        xyz="-6.9389E-18 0 0.0635"
        rpy="0 0 0" />
      <mass
        value="0.5121" />
      <inertia
        ixx="0.00086037"
        ixy="-3.3902E-20"
        ixz="0"
        iyy="0.00086037"
        iyz="-7.4029E-21"
        izz="0.00034415" />
    </inertial>
    <visual>
      <origin
        xyz="0 0 0"
        rpy="0 0 0" />
      <geometry>
        <mesh
          filename="package://robot_description/meshes/laser_link.STL" />
      </geometry>
      <material
        name="">
        <color
          rgba="0 0 0 .7" />
      </material>
    </visual>
    <collision>
      <origin
        xyz="0 0 0"
        rpy="0 0 0" />
      <geometry>
        <mesh
          filename="package://robot_description/meshes/laser_link.STL" />
      </geometry>
    </collision>
  </link>
  <joint
    name="laser_joint"
    type="fixed">
    <origin
      xyz="-0.034925 0.34722 0.34608"
      rpy="3.1416 0 0" />
    <parent
      link="base_link" />
    <child
      link="laser_link" />
    <axis
      xyz="0 0 0" />
  </joint>
</robot>
